<robot
  name="schunkPG70_description">
  <link
    name="tool_link">
    <inertial>
      <origin
        xyz="0.0613477117811421 0.0144913561810834 -3.33375955913809E-07"
        rpy="0 0 0" />
      <mass
        value="1.08662283556797" />
      <inertia
        ixx="0.00243104372961667"
        ixy="-4.08331678526195E-06"
        ixz="-5.57822500256459E-07"
        iyy="0.00137576199676778"
        iyz="-2.0124086350385E-07"
        izz="0.00271807103917331" />
    </inertial>
    <visual>
      <origin
        xyz="0 0 0"
        rpy="0 0 0" />
      <geometry>
        <mesh
          filename="package://schunkPG70_description/meshes/tool_link.STL" />
      </geometry>
      <material
        name="">
        <color
          rgba="0.549019608 0.450980392 0.235294118 1" />
      </material>
    </visual>
    <collision>
      <origin
        xyz="0 0 0"
        rpy="0 0 0" />
      <geometry>
        <mesh
          filename="package://schunkPG70_description/meshes/tool_link.STL" />
      </geometry>
    </collision>
  </link>
  <link
    name="gripper_a_frame">
    <inertial>
      <origin
        xyz="-0.00671706032221001 0.00436337189311105 0.00663136324588428"
        rpy="0 0 0" />
      <mass
        value="0.0203342527020743" />
      <inertia
        ixx="1.63180683306796E-05"
        ixy="1.92796102278683E-06"
        ixz="-6.88638129378754E-07"
        iyy="4.10056189010877E-06"
        iyz="-2.20186959771101E-06"
        izz="1.72210919808996E-05" />
    </inertial>
    <visual>
      <origin
        xyz="0 0 0"
        rpy="0 0 0" />
      <geometry>
        <mesh
          filename="package://schunkPG70_description/meshes/gripper_frame.STL" />
      </geometry>
      <material
        name="">
        <color
          rgba="0.12157 0.12157 0.12157 1" />
      </material>
    </visual>
    <collision>
      <origin
        xyz="0 0 0"
        rpy="0 0 0" />
      <geometry>
        <mesh
          filename="package://schunkPG70_description/meshes/gripper_frame.STL" />
      </geometry>
    </collision>
  </link>
  <joint
    name="gripper_a"
    type="prismatic">
    <origin
      xyz="0.122275 0.0322999 0.000250099999999993"
      rpy="-3.14159265358979 -9.0205620750794E-17 1.5707963267949" />
    <parent
      link="tool_link" />
    <child
      link="gripper_a_frame" />
    <axis
      xyz="-1 0 0" />
    <limit
      lower="0"
      upper="0.032"
      effort="0"
      velocity="0" />
  </joint>
  <link
    name="gripper_b_frame">
    <inertial>
      <origin
        xyz="-0.00671706032221 0.00436337189311103 0.00663136324588428"
        rpy="0 0 0" />
      <mass
        value="0.0203342527020743" />
      <inertia
        ixx="1.63180683306796E-05"
        ixy="1.92796102278682E-06"
        ixz="-6.88638129378752E-07"
        iyy="4.10056189010876E-06"
        iyz="-2.20186959771101E-06"
        izz="1.72210919808996E-05" />
    </inertial>
    <visual>
      <origin
        xyz="0 0 0"
        rpy="0 0 0" />
      <geometry>
        <mesh
          filename="package://schunkPG70_description/meshes/gripper_frame.STL" />
      </geometry>
      <material
        name="">
        <color
          rgba="0.12157 0.12157 0.12157 1" />
      </material>
    </visual>
    <collision>
      <origin
        xyz="0 0 0"
        rpy="0 0 0" />
      <geometry>
        <mesh
          filename="package://schunkPG70_description/meshes/gripper_frame.STL" />
      </geometry>
    </collision>
  </link>
  <joint
    name="gripper_b"
    type="prismatic">
    <origin
      xyz="0.122275 -0.0323001 -0.00024990000000001"
      rpy="-5.17444897013869E-31 9.0205620750794E-17 -1.5707963267949" />
    <parent
      link="tool_link" />
    <child
      link="gripper_b_frame" />
    <axis
      xyz="-1 0 0" />
    <mimic
      joint="gripper_a" />
    <limit
      lower="0"
      upper="0.032"
      effort="0"
      velocity="0" />
  </joint>
</robot>
