<robot
  name="schunkPG70_description">
  <link
    name="tool_frame">
    <inertial>
      <origin
        xyz="0.0428167000112532 -0.0154627513584462 9.8365932868694E-09"
        rpy="0 0 0" />
      <mass
        value="0.965844004259551" />
      <inertia
        ixx="0.00224902870939144"
        ixy="5.51350675753637E-05"
        ixz="7.90091741737282E-07"
        iyy="0.00107518524881277"
        iyz="-2.01318847698817E-07"
        izz="0.00233341323935938" />
    </inertial>
    <visual>
      <origin
        xyz="0 0 0"
        rpy="0 0 0" />
      <geometry>
        <mesh
          filename="package://schunkPG70_description/meshes/tool_frame.STL" />
      </geometry>
      <material
        name="">
        <color
          rgba="0.549019608 0.450980392 0.235294118 1" />
      </material>
    </visual>
    <collision>
      <origin
        xyz="0 0 0"
        rpy="0 0 0" />
      <geometry>
        <mesh
          filename="package://schunkPG70_description/meshes/tool_frame.STL" />
      </geometry>
    </collision>
  </link>
  <link
    name="gripper_a_frame">
    <inertial>
      <origin
        xyz="-0.0067171 0.0043634 0.0066314"
        rpy="0 0 0" />
      <mass
        value="0.020334" />
      <inertia
        ixx="1.6318E-05"
        ixy="1.928E-06"
        ixz="-6.8864E-07"
        iyy="4.1006E-06"
        iyz="-2.2019E-06"
        izz="1.7221E-05" />
    </inertial>
    <visual>
      <origin
        xyz="0 0 0"
        rpy="0 0 0" />
      <geometry>
        <mesh
          filename="package://schunkPG70_description/meshes/gripper_frame.STL" />
      </geometry>
      <material
        name="">
        <color
          rgba="0.12157 0.12157 0.12157 1" />
      </material>
    </visual>
    <collision>
      <origin
        xyz="0 0 0"
        rpy="0 0 0" />
      <geometry>
        <mesh
          filename="package://schunkPG70_description/meshes/gripper_frame.STL" />
      </geometry>
    </collision>
  </link>
  <joint
    name="gripper_a"
    type="prismatic">
    <origin
      xyz="0.0985 -0.0323 -0.00025"
      rpy="0 0 -1.5708" />
    <parent
      link="tool_frame" />
    <child
      link="gripper_a_frame" />
    <axis
      xyz="-1 0 0" />
    <limit
      lower="0"
      upper="0.032"
      effort="0"
      velocity="0" />
  </joint>
  <link
    name="gripper_b_frame">
    <inertial>
      <origin
        xyz="-0.00671706032221001 0.00436337189311103 0.00663136324588428"
        rpy="0 0 0" />
      <mass
        value="0.0203342527020743" />
      <inertia
        ixx="1.63180683306795E-05"
        ixy="1.92796102278682E-06"
        ixz="-6.88638129378752E-07"
        iyy="4.10056189010876E-06"
        iyz="-2.201869597711E-06"
        izz="1.72210919808996E-05" />
    </inertial>
    <visual>
      <origin
        xyz="0 0 0"
        rpy="0 0 0" />
      <geometry>
        <mesh
          filename="package://schunkPG70_description/meshes/gripper_frame.STL" />
      </geometry>
      <material
        name="">
        <color
          rgba="0.12156862745098 0.12156862745098 0.12156862745098 1" />
      </material>
    </visual>
    <collision>
      <origin
        xyz="0 0 0"
        rpy="0 0 0" />
      <geometry>
        <mesh
          filename="package://schunkPG70_description/meshes/gripper_frame.STL" />
      </geometry>
    </collision>
  </link>
  <joint
    name="gripper_b"
    type="prismatic">
    <origin
      xyz="0.0985 0.0323 0.00025"
      rpy="3.1416 0 1.5708" />
    <parent
      link="tool_frame" />
    <child
      link="gripper_b_frame" />
    <axis
      xyz="-1 0 0" />
    <mimic
      joint="gripper_a" />
    <limit
      lower="0"
      upper="0.032"
      effort="0"
      velocity="0" />
  </joint>
</robot>
